<?xml version="1.0"?>
<sdf version="1.5">
    <model name="mobile_robot">
        <static>false</static>
        <link name="base_link">
            <visual name="visual">
            <geometry>
                <cylinder length="0.1" radius="0.1"/>
            </geometry>
            </visual>
        </link>
        <joint name="base_joint" type="fixed">
            <origin xyz="0 0 0"/>
            <parent link="world"/>
            <child link="base_link"/>
        </joint>
        <link name="left_wheel">
            <visual name="visual">
            <geometry>
                <cylinder length="0.05" radius="0.05"/>
            </geometry>
            </visual>
        </link>
        <joint name="left_wheel_joint" type="continuous">
            <origin xyz="-0.1 0 0"/>
            <parent link="base_link"/>
            <child link="left_wheel"/>
            <axis xyz="0 0 1"/>
        </joint>
        <link name="right_wheel">
            <visual name="visual">
            <geometry>
                <cylinder length="0.05" radius="0.05"/>
            </geometry>
            </visual>
        </link>
        <joint name="right_wheel_joint" type="continuous">
            <origin xyz="0.1 0 0"/>
            <parent link="base_link"/>
            <child link="right_wheel"/>
            <axis xyz="0 0 1"/>
        </joint>
    </model>
</sdf>