<?xml version="1.0"?>

<robot xmlns:xacro="http://www.ros.org/wiki/xacro" name="mobile_robot">
  <!--  -->
  <!--Color palette for robot--> 
  <material name="black">
    <color rgba="0.0 0.0 0.0 1.0"/>
  </material>
  <material name="blue">
    <color rgba="0.203125 0.23828125 0.28515625 1.0"/>
  </material>
  <material name="red">
    <color rgba="0.80078125 0.12890625 0.1328125 1.0"/>
  </material>

  <!--reference of color to robot links-->
  <gazebo reference="base_link">
    <material>Gazebo/Blue</material>
  </gazebo>
  <gazebo reference="left_back_wheel_link">
    <material>Gazebo/Black</material>
    <kp>1000000.0</kp> <!-- kp and kd for rubber -->
	<kd>100.0</kd>
	<mu1>1.0</mu1>
	<mu2>1.0</mu2>
	<maxVel>1.0</maxVel>
	<minDepth>0.00</minDepth>
  </gazebo>
  <gazebo reference="right_back_wheel_link">
    <material>Gazebo/Black</material>
    <kp>1000000.0</kp> <!-- kp and kd for rubber -->
	<kd>100.0</kd>
	<mu1>1.0</mu1>
	<mu2>1.0</mu2>
	<maxVel>1.0</maxVel>
	<minDepth>0.00</minDepth>
  </gazebo>
  <gazebo reference="left_front_wheel_link">
    <material>Gazebo/Black</material>
    <kp>1000000.0</kp> <!-- kp and kd for rubber -->
	<kd>100.0</kd>
	<mu1>1.0</mu1>
	<mu2>1.0</mu2>
	<maxVel>1.0</maxVel>
	<minDepth>0.00</minDepth>
  </gazebo>
  <gazebo reference="ultrasonic_sensor_link">
    <material>Gazebo/Red</material>
  </gazebo>
  <gazebo reference="right_front_wheel_link">
    <material>Gazebo/Black</material>
    <kp>1000000.0</kp> <!-- kp and kd for rubber -->
	<kd>100.0</kd>
	<mu1>1.0</mu1>
	<mu2>1.0</mu2>
	<maxVel>1.0</maxVel>
	<minDepth>0.00</minDepth>
  </gazebo>

  <!-- Define the mobile robot's base -->
  <link name="base_footprint">
    <inertia m="1.0" w="0.001" h="0.001" d="0.001"/>
    <visual>
        <origin xyz="0 0 0" rpy="0 0 0" />
        <geometry>
            <box size="0.001 0.001 0.001" />
        </geometry>
    </visual>
  </link>
  <link name="base_link">
    <inertial>
      <mass value="1.0" />
      <origin xyz="0 0 0.1" />
      <inertia ixx="0.083" ixy="0.0" ixz="0.0" iyy="0.083" iyz="0.0" izz="0.083" />
    </inertial>
    <collision>
      <geometry>
        <box size=".6 .4 .1" />
      </geometry>
    </collision>
    <visual>
      <geometry>
        <box size=".6 .4 .1" />
      </geometry>
    </visual>
  </link>

  <!--base_link to base_footprint Joint-->
  <joint name="base_link_joint" type="fixed">
    <origin xyz="0 0 0.04" rpy="0 0 0" />
    <parent link="base_footprint"/>
    <child link="base_link" />
  </joint>

  <!-- Define the wheels -->
  <link name="left_back_wheel_link">
    <inertial>
      <mass value="0.1" />
      <origin xyz="0 0 0" />
      <inertia ixx="0.1" ixy="0.0" ixz="0.0" iyy="0.1" iyz="0.0" izz="0.1" />
    </inertial>
    <collision>
    <origin xyz="0 0 -0.05" rpy=" 0 0 0"/>
      <geometry>
        <sphere radius="0.05" />
      </geometry>
    </collision>
    <visual>
    <origin xyz="0 0 -0.05" rpy=" 0 0 0"/>
      <geometry>
        <sphere radius="0.05" />
      </geometry>
    </visual>
  </link>

  <joint name="left_back_wheel_joint" type="continuous">
    <parent link="base_link" />
    <child link="left_back_wheel_link" />
    <origin xyz="-0.15 -0.18 0" rpy="0 0 0" />
    <axis xyz="0 0 1" />
    <limit effort="10000" velocity="1000" />
	<dynamics damping="1.0" friction="1.0" />
  </joint>

  <!--   Joint transmission for left back wheel -->
  <transmission name="left_back_wheel_transmission">
    <type>transmission_interface/SimpleTransmission</type>
    <joint name="left_back_wheel_joint">
      <hardwareInterface>hardware_interface/VelocityJointInterface</hardwareInterface>  
    </joint>
    <actuator name="left_back_wheel_actuator">
      <mechanicalReduction>1</mechanicalReduction>
      <hardwareInterface>VelocityJointInterface</hardwareInterface>
    </actuator>
  </transmission>

  <link name="left_front_wheel_link">
    <inertial>
      <mass value="0.1" />
      <origin xyz="0 0 0" />
      <inertia ixx="0.1" ixy="0.0" ixz="0.0" iyy="0.1" iyz="0.0" izz="0.1" />
    </inertial>
    <collision>
    <origin xyz="0 0 -0.05" rpy=" 0 0 0"/>
      <geometry>
        <sphere radius="0.05" />
      </geometry>
    </collision>
    <visual>
    <origin xyz="0 0 -0.05" rpy=" 0 0 0"/>
      <geometry>
        <sphere radius="0.05" />
      </geometry>
    </visual>
  </link>

  <joint name="left_front_wheel_joint" type="continuous">
    <parent link="base_link" />
    <child link="left_front_wheel_link" />
    <origin xyz="0.15 -0.18 0" rpy="0 0 0" />
    <axis xyz="0 0 1" />
    <limit effort="10000" velocity="1000" />
	<dynamics damping="1.0" friction="1.0" />
  </joint>

  <!--   Joint transmission for left front wheel -->
  <transmission name="left_front_wheel_transmission">
    <type>transmission_interface/SimpleTransmission</type>
    <joint name="left_front_wheel_joint">
      <hardwareInterface>hardware_interface/VelocityJointInterface</hardwareInterface>  
    </joint>
    <actuator name="left_front_wheel_actuator">
      <mechanicalReduction>1</mechanicalReduction>
      <hardwareInterface>VelocityJointInterface</hardwareInterface>
    </actuator>
  </transmission>

  <link name="right_back_wheel_link">
    <inertial>
      <mass value="0.1" />
      <origin xyz="0 0 0" />
      <inertia ixx="0.1" ixy="0.0" ixz="0.0" iyy="0.1" iyz="0.0" izz="0.1" />
    </inertial>
    <collision>
    <origin xyz="0 0 -0.05" rpy=" 0 0 0"/>
      <geometry>
        <sphere radius="0.05" />
      </geometry>
    </collision>
    <visual>
    <origin xyz="0 0 -0.05" rpy=" 0 0 0"/>
      <geometry>
        <sphere radius="0.05" />
      </geometry>
    </visual>
  </link>

  <joint name="right_back_wheel_joint" type="continuous">
    <parent link="base_link" />
    <child link="right_back_wheel_link" />
    <origin xyz="-0.15 0.18 0" rpy="0 0 0" />
    <axis xyz="0 0 1" />
    <limit effort="10000" velocity="1000" />
	<dynamics damping="1.0" friction="1.0" />
  </joint>

  <!-- Joint transmission for right back wheel -->
  <transmission name="right_back_wheel_transmission">
    <type>transmission_interface/SimpleTransmission</type>
    <joint name="right_back_wheel_joint">
      <hardwareInterface>hardware_interface/VelocityJointInterface</hardwareInterface>  
    </joint>
    <actuator name="right_back_wheel_actuator">
      <mechanicalReduction>1</mechanicalReduction>
      <hardwareInterface>VelocityJointInterface</hardwareInterface>
    </actuator>
  </transmission>

  <link name="right_front_wheel_link">
    <inertial>
      <mass value="0.1" />
      <origin xyz="0 0 0" />
      <inertia ixx="0.1" ixy="0.0" ixz="0.0" iyy="0.1" iyz="0.0" izz="0.1" />
    </inertial>
    <collision>
    <origin xyz="0 0 -0.05" rpy=" 0 0 0"/>
      <geometry>
        <sphere radius="0.05" />
      </geometry>
    </collision>
    <visual>
    <origin xyz="0 0 -0.05" rpy=" 0 0 0"/>
      <geometry>
        <sphere radius="0.05" />
      </geometry>
    </visual>
  </link>

  <joint name="right_front_wheel_joint" type="continuous">
    <parent link="base_link" />
    <child link="right_front_wheel_link" />
    <origin xyz="0.15 0.18 0" rpy="0 0 0" />
    <axis xyz="0 0 1" />
    <limit effort="10000" velocity="1000" />
	<dynamics damping="1.0" friction="1.0" />
  </joint>

  <!-- Joint transmission for right front wheel -->
  <transmission name="right_front_wheel_transmission">
    <type>transmission_interface/SimpleTransmission</type>
    <joint name="right_front_wheel_joint">
      <hardwareInterface>hardware_interface/VelocityJointInterface</hardwareInterface>  
    </joint>
    <actuator name="right_front_wheel_actuator">
      <mechanicalReduction>1</mechanicalReduction>
      <hardwareInterface>VelocityJointInterface</hardwareInterface>
    </actuator>
  </transmission>

  <link name="ultrasonic_sensor_link">
    <collision>
      <geometry>
        <box size="0.1 0.1 0.07"/>
      </geometry>
    </collision>
    <visual>
      <geometry>
        <box size="0.1 0.1 0.07"/>
      </geometry>
    </visual>
  </link>

  <joint name="ultrasonic_sensor_joint" type="fixed">
    <origin xyz="0.13 0 0.1"/>
    <parent link="base_link"/>
    <child link="ultrasonic_sensor_link"/>
  </joint>

  <!-- <gazebo>
    <plugin name="gazebo_ros_control" filename= "libgazebo_ros_control.so">
    </plugin>
  </gazebo> -->

  <xacro:include filename="$(find my_robot)/urdf/include/urdf1.gazebo" />
</robot>